{
 "cells": [
  {
   "cell_type": "code",
   "execution_count": 1,
   "metadata": {},
   "outputs": [],
   "source": [
    "import os"
   ]
  },
  {
   "cell_type": "code",
   "execution_count": 2,
   "metadata": {},
   "outputs": [
    {
     "data": {
      "text/plain": [
       "'c:\\\\Users\\\\mayan\\\\Deep learning\\\\project2\\\\1\\\\Chicken disease classfication\\\\Chicken-Disease-Classification--Project\\\\research'"
      ]
     },
     "execution_count": 2,
     "metadata": {},
     "output_type": "execute_result"
    }
   ],
   "source": [
    "%pwd"
   ]
  },
  {
   "cell_type": "code",
   "execution_count": 3,
   "metadata": {},
   "outputs": [],
   "source": [
    "os.chdir(\"../\")"
   ]
  },
  {
   "cell_type": "code",
   "execution_count": 4,
   "metadata": {},
   "outputs": [
    {
     "data": {
      "text/plain": [
       "'c:\\\\Users\\\\mayan\\\\Deep learning\\\\project2\\\\1\\\\Chicken disease classfication\\\\Chicken-Disease-Classification--Project'"
      ]
     },
     "execution_count": 4,
     "metadata": {},
     "output_type": "execute_result"
    }
   ],
   "source": [
    "%pwd"
   ]
  },
  {
   "cell_type": "code",
   "execution_count": 5,
   "metadata": {},
   "outputs": [],
   "source": [
    "from dataclasses import dataclass\n",
    "from pathlib import Path\n",
    "\n",
    "\n",
    "@dataclass(frozen=True)\n",
    "class PrepareCallbacksConfig:\n",
    "    root_dir: Path\n",
    "    tensorboard_root_log_dir: Path\n",
    "    checkpoint_model_filepath: Path"
   ]
  },
  {
   "cell_type": "code",
   "execution_count": 7,
   "metadata": {},
   "outputs": [],
   "source": [
    "import os\n",
    "import sys\n",
    "# Add the src directory to Python path\n",
    "sys.path.append(os.path.abspath('src'))\n",
    "# OR if you're inside a notebook folder:\n",
    "sys.path.append(os.path.abspath('../src'))"
   ]
  },
  {
   "cell_type": "code",
   "execution_count": 8,
   "metadata": {},
   "outputs": [],
   "source": [
    "from cnnClassifier.constants import *\n",
    "from cnnClassifier.utils.common import read_yaml, create_directories"
   ]
  },
  {
   "cell_type": "code",
   "execution_count": 9,
   "metadata": {},
   "outputs": [],
   "source": [
    "class ConfigurationManager:\n",
    "    def __init__(\n",
    "        self, \n",
    "        config_filepath = CONFIG_FILE_PATH,\n",
    "        params_filepath = PARAMS_FILE_PATH):\n",
    "        self.config = read_yaml(config_filepath)\n",
    "        self.params = read_yaml(params_filepath)\n",
    "        create_directories([self.config.artifacts_root])\n",
    "\n",
    "\n",
    "    \n",
    "    def get_prepare_callback_config(self) -> PrepareCallbacksConfig:\n",
    "        config = self.config.prepare_callbacks\n",
    "        model_ckpt_dir = os.path.dirname(config.checkpoint_model_filepath)\n",
    "        create_directories([\n",
    "            Path(model_ckpt_dir),\n",
    "            Path(config.tensorboard_root_log_dir)\n",
    "        ])\n",
    "\n",
    "        prepare_callback_config = PrepareCallbacksConfig(\n",
    "            root_dir=Path(config.root_dir),\n",
    "            tensorboard_root_log_dir=Path(config.tensorboard_root_log_dir),\n",
    "            checkpoint_model_filepath=Path(config.checkpoint_model_filepath)\n",
    "        )\n",
    "\n",
    "        return prepare_callback_config"
   ]
  },
  {
   "cell_type": "code",
   "execution_count": 10,
   "metadata": {},
   "outputs": [],
   "source": [
    "import os\n",
    "import urllib.request as request\n",
    "from zipfile import ZipFile\n",
    "import tensorflow as tf\n",
    "import time"
   ]
  },
  {
   "cell_type": "code",
   "execution_count": null,
   "metadata": {},
   "outputs": [],
   "source": [
    "from box import ConfigBox\n",
    "\n",
    "class PrepareCallback:\n",
    "    def __init__(self, config: PrepareCallbacksConfig):\n",
    "        self.config = config\n",
    "\n",
    "\n",
    "    \n",
    "    @property\n",
    "    def _create_tb_callbacks(self):\n",
    "        timestamp = time.strftime(\"%Y-%m-%d-%H-%M-%S\")\n",
    "        tb_running_log_dir = os.path.join(\n",
    "            self.config.tensorboard_root_log_dir,\n",
    "            f\"tb_logs_at_{timestamp}\",\n",
    "        )\n",
    "        return tf.keras.callbacks.TensorBoard(log_dir=tb_running_log_dir)\n",
    "    \n",
    "\n",
    "    @property\n",
    "    def _create_ckpt_callbacks(self):\n",
    "        return tf.keras.callbacks.ModelCheckpoint(\n",
    "            filepath=self.config.checkpoint_model_filepath,\n",
    "            save_best_only=True\n",
    "        )\n",
    "\n",
    "\n",
    "    def get_tb_ckpt_callbacks(self):\n",
    "        return [\n",
    "            self._create_tb_callbacks,\n",
    "            self._create_ckpt_callbacks\n",
    "        ]"
   ]
  },
  {
   "cell_type": "code",
   "execution_count": 12,
   "metadata": {},
   "outputs": [
    {
     "name": "stdout",
     "output_type": "stream",
     "text": [
      "[2024-11-12 20:00:51,476: INFO: common: yaml file: config\\config.yaml loaded successfully]\n",
      "[2024-11-12 20:00:51,478: INFO: common: yaml file: params.yaml loaded successfully]\n",
      "[2024-11-12 20:00:51,483: INFO: common: created directory at: artifacts]\n"
     ]
    },
    {
     "ename": "BoxKeyError",
     "evalue": "\"'ConfigBox' object has no attribute 'prepare_callbacks'\"",
     "output_type": "error",
     "traceback": [
      "\u001b[1;31m---------------------------------------------------------------------------\u001b[0m",
      "\u001b[1;31mKeyError\u001b[0m                                  Traceback (most recent call last)",
      "File \u001b[1;32mc:\\Users\\mayan\\AppData\\Local\\Programs\\Python\\Python39\\lib\\site-packages\\box\\box.py:593\u001b[0m, in \u001b[0;36mbox.box.Box.__getitem__\u001b[1;34m()\u001b[0m\n",
      "\u001b[1;31mKeyError\u001b[0m: 'prepare_callbacks'",
      "\nThe above exception was the direct cause of the following exception:\n",
      "\u001b[1;31mBoxKeyError\u001b[0m                               Traceback (most recent call last)",
      "File \u001b[1;32mc:\\Users\\mayan\\AppData\\Local\\Programs\\Python\\Python39\\lib\\site-packages\\box\\box.py:632\u001b[0m, in \u001b[0;36mbox.box.Box.__getattr__\u001b[1;34m()\u001b[0m\n",
      "File \u001b[1;32mc:\\Users\\mayan\\AppData\\Local\\Programs\\Python\\Python39\\lib\\site-packages\\box\\box.py:620\u001b[0m, in \u001b[0;36mbox.box.Box.__getitem__\u001b[1;34m()\u001b[0m\n",
      "\u001b[1;31mBoxKeyError\u001b[0m: \"'prepare_callbacks'\"",
      "\nDuring handling of the above exception, another exception occurred:\n",
      "\u001b[1;31mAttributeError\u001b[0m                            Traceback (most recent call last)",
      "File \u001b[1;32mc:\\Users\\mayan\\AppData\\Local\\Programs\\Python\\Python39\\lib\\site-packages\\box\\box.py:634\u001b[0m, in \u001b[0;36mbox.box.Box.__getattr__\u001b[1;34m()\u001b[0m\n",
      "\u001b[1;31mAttributeError\u001b[0m: 'ConfigBox' object has no attribute 'prepare_callbacks'",
      "\nThe above exception was the direct cause of the following exception:\n",
      "\u001b[1;31mBoxKeyError\u001b[0m                               Traceback (most recent call last)",
      "File \u001b[1;32mc:\\Users\\mayan\\AppData\\Local\\Programs\\Python\\Python39\\lib\\site-packages\\box\\config_box.py:29\u001b[0m, in \u001b[0;36mbox.config_box.ConfigBox.__getattr__\u001b[1;34m()\u001b[0m\n",
      "File \u001b[1;32mc:\\Users\\mayan\\AppData\\Local\\Programs\\Python\\Python39\\lib\\site-packages\\box\\box.py:648\u001b[0m, in \u001b[0;36mbox.box.Box.__getattr__\u001b[1;34m()\u001b[0m\n",
      "\u001b[1;31mBoxKeyError\u001b[0m: \"'ConfigBox' object has no attribute 'prepare_callbacks'\"",
      "\nDuring handling of the above exception, another exception occurred:\n",
      "\u001b[1;31mKeyError\u001b[0m                                  Traceback (most recent call last)",
      "File \u001b[1;32mc:\\Users\\mayan\\AppData\\Local\\Programs\\Python\\Python39\\lib\\site-packages\\box\\box.py:593\u001b[0m, in \u001b[0;36mbox.box.Box.__getitem__\u001b[1;34m()\u001b[0m\n",
      "\u001b[1;31mKeyError\u001b[0m: 'prepare_callbacks'",
      "\nThe above exception was the direct cause of the following exception:\n",
      "\u001b[1;31mBoxKeyError\u001b[0m                               Traceback (most recent call last)",
      "File \u001b[1;32mc:\\Users\\mayan\\AppData\\Local\\Programs\\Python\\Python39\\lib\\site-packages\\box\\box.py:632\u001b[0m, in \u001b[0;36mbox.box.Box.__getattr__\u001b[1;34m()\u001b[0m\n",
      "File \u001b[1;32mc:\\Users\\mayan\\AppData\\Local\\Programs\\Python\\Python39\\lib\\site-packages\\box\\box.py:620\u001b[0m, in \u001b[0;36mbox.box.Box.__getitem__\u001b[1;34m()\u001b[0m\n",
      "\u001b[1;31mBoxKeyError\u001b[0m: \"'prepare_callbacks'\"",
      "\nDuring handling of the above exception, another exception occurred:\n",
      "\u001b[1;31mAttributeError\u001b[0m                            Traceback (most recent call last)",
      "File \u001b[1;32mc:\\Users\\mayan\\AppData\\Local\\Programs\\Python\\Python39\\lib\\site-packages\\box\\box.py:634\u001b[0m, in \u001b[0;36mbox.box.Box.__getattr__\u001b[1;34m()\u001b[0m\n",
      "\u001b[1;31mAttributeError\u001b[0m: 'ConfigBox' object has no attribute 'prepare_callbacks'",
      "\nThe above exception was the direct cause of the following exception:\n",
      "\u001b[1;31mBoxKeyError\u001b[0m                               Traceback (most recent call last)",
      "Cell \u001b[1;32mIn[12], line 8\u001b[0m\n\u001b[0;32m      5\u001b[0m     callback_list \u001b[38;5;241m=\u001b[39m prepare_callbacks\u001b[38;5;241m.\u001b[39mget_tb_ckpt_callbacks()\n\u001b[0;32m      7\u001b[0m \u001b[38;5;28;01mexcept\u001b[39;00m \u001b[38;5;167;01mException\u001b[39;00m \u001b[38;5;28;01mas\u001b[39;00m e:\n\u001b[1;32m----> 8\u001b[0m     \u001b[38;5;28;01mraise\u001b[39;00m e\n",
      "Cell \u001b[1;32mIn[12], line 3\u001b[0m\n\u001b[0;32m      1\u001b[0m \u001b[38;5;28;01mtry\u001b[39;00m:\n\u001b[0;32m      2\u001b[0m     config \u001b[38;5;241m=\u001b[39m ConfigurationManager()\n\u001b[1;32m----> 3\u001b[0m     prepare_callbacks_config \u001b[38;5;241m=\u001b[39m \u001b[43mconfig\u001b[49m\u001b[38;5;241;43m.\u001b[39;49m\u001b[43mget_prepare_callback_config\u001b[49m\u001b[43m(\u001b[49m\u001b[43m)\u001b[49m\n\u001b[0;32m      4\u001b[0m     prepare_callbacks \u001b[38;5;241m=\u001b[39m PrepareCallback(config\u001b[38;5;241m=\u001b[39mprepare_callbacks_config)\n\u001b[0;32m      5\u001b[0m     callback_list \u001b[38;5;241m=\u001b[39m prepare_callbacks\u001b[38;5;241m.\u001b[39mget_tb_ckpt_callbacks()\n",
      "Cell \u001b[1;32mIn[9], line 13\u001b[0m, in \u001b[0;36mConfigurationManager.get_prepare_callback_config\u001b[1;34m(self)\u001b[0m\n\u001b[0;32m     12\u001b[0m \u001b[38;5;28;01mdef\u001b[39;00m \u001b[38;5;21mget_prepare_callback_config\u001b[39m(\u001b[38;5;28mself\u001b[39m) \u001b[38;5;241m-\u001b[39m\u001b[38;5;241m>\u001b[39m PrepareCallbacksConfig:\n\u001b[1;32m---> 13\u001b[0m     config \u001b[38;5;241m=\u001b[39m \u001b[38;5;28;43mself\u001b[39;49m\u001b[38;5;241;43m.\u001b[39;49m\u001b[43mconfig\u001b[49m\u001b[38;5;241;43m.\u001b[39;49m\u001b[43mprepare_callbacks\u001b[49m\n\u001b[0;32m     14\u001b[0m     model_ckpt_dir \u001b[38;5;241m=\u001b[39m os\u001b[38;5;241m.\u001b[39mpath\u001b[38;5;241m.\u001b[39mdirname(config\u001b[38;5;241m.\u001b[39mcheckpoint_model_filepath)\n\u001b[0;32m     15\u001b[0m     create_directories([\n\u001b[0;32m     16\u001b[0m         Path(model_ckpt_dir),\n\u001b[0;32m     17\u001b[0m         Path(config\u001b[38;5;241m.\u001b[39mtensorboard_root_log_dir)\n\u001b[0;32m     18\u001b[0m     ])\n",
      "File \u001b[1;32mc:\\Users\\mayan\\AppData\\Local\\Programs\\Python\\Python39\\lib\\site-packages\\box\\config_box.py:31\u001b[0m, in \u001b[0;36mbox.config_box.ConfigBox.__getattr__\u001b[1;34m()\u001b[0m\n",
      "File \u001b[1;32mc:\\Users\\mayan\\AppData\\Local\\Programs\\Python\\Python39\\lib\\site-packages\\box\\box.py:648\u001b[0m, in \u001b[0;36mbox.box.Box.__getattr__\u001b[1;34m()\u001b[0m\n",
      "\u001b[1;31mBoxKeyError\u001b[0m: \"'ConfigBox' object has no attribute 'prepare_callbacks'\""
     ]
    }
   ],
   "source": [
    "try:\n",
    "    config = ConfigurationManager()\n",
    "    prepare_callbacks_config = config.get_prepare_callback_config()\n",
    "    prepare_callbacks = PrepareCallback(config=prepare_callbacks_config)\n",
    "    callback_list = prepare_callbacks.get_tb_ckpt_callbacks()\n",
    "    \n",
    "except Exception as e:\n",
    "    raise e"
   ]
  },
  {
   "cell_type": "code",
   "execution_count": null,
   "metadata": {},
   "outputs": [],
   "source": []
  }
 ],
 "metadata": {
  "kernelspec": {
   "display_name": "Python 3",
   "language": "python",
   "name": "python3"
  },
  "language_info": {
   "codemirror_mode": {
    "name": "ipython",
    "version": 3
   },
   "file_extension": ".py",
   "mimetype": "text/x-python",
   "name": "python",
   "nbconvert_exporter": "python",
   "pygments_lexer": "ipython3",
   "version": "3.9.7"
  }
 },
 "nbformat": 4,
 "nbformat_minor": 2
}
